

Error in on_message:
Traceback (most recent call last):
  File "/home/runner/workspace/.pythonlibs/lib/python3.11/site-packages/discord/client.py", line 481, in _run_event
    await coro(*args, **kwargs)
  File "/home/runner/workspace/main.py", line 305, in on_message
    await message.author.timeout_for(60)  # Timeout for 1 minute
          ^^^^^^^^^^^^^^^^^^^^^^^^^^
AttributeError: 'Member' object has no attribute 'timeout_for'


Error in on_message:
Traceback (most recent call last):
  File "/home/runner/workspace/.pythonlibs/lib/python3.11/site-packages/discord/client.py", line 481, in _run_event
    await coro(*args, **kwargs)
  File "/home/runner/workspace/main.py", line 299, in on_message
    await message.author.timeout_for(60)  # Timeout for 1 minute
          ^^^^^^^^^^^^^^^^^^^^^^^^^^
AttributeError: 'Member' object has no attribute 'timeout_for'


Error in on_message:
Traceback (most recent call last):
  File "/home/runner/workspace/.pythonlibs/lib/python3.11/site-packages/discord/client.py", line 481, in _run_event
    await coro(*args, **kwargs)
  File "/home/runner/workspace/main.py", line 303, in on_message
    await message.author.timeout_for(60)  # Timeout for 1 minute
          ^^^^^^^^^^^^^^^^^^^^^^^^^^
AttributeError: 'Member' object has no attribute 'timeout_for'


Error in on_message:
Traceback (most recent call last):
  File "/home/runner/workspace/.pythonlibs/lib/python3.11/site-packages/discord/client.py", line 481, in _run_event
    await coro(*args, **kwargs)
  File "/home/runner/workspace/main.py", line 305, in on_message
    await message.author.timeout_for(60)  # Timeout for 1 minute
          ^^^^^^^^^^^^^^^^^^^^^^^^^^
AttributeError: 'Member' object has no attribute 'timeout_for'


Error in on_message:
Traceback (most recent call last):
  File "/home/runner/workspace/.pythonlibs/lib/python3.11/site-packages/discord/client.py", line 481, in _run_event
    await coro(*args, **kwargs)
  File "/home/runner/workspace/main.py", line 305, in on_message
    await message.author.timeout_for(60)  # Timeout for 1 minute
          ^^^^^^^^^^^^^^^^^^^^^^^^^^
AttributeError: 'Member' object has no attribute 'timeout_for'


Error in on_message:
Traceback (most recent call last):
  File "/home/runner/workspace/.pythonlibs/lib/python3.11/site-packages/discord/client.py", line 481, in _run_event
    await coro(*args, **kwargs)
  File "/home/runner/workspace/main.py", line 311, in on_message
    await message.author.timeout_for(60)  # Timeout for 1 minute
          ^^^^^^^^^^^^^^^^^^^^^^^^^^
AttributeError: 'Member' object has no attribute 'timeout_for'


Error in on_voice_state_update:
Traceback (most recent call last):
  File "/home/container/.local/lib/python3.11/site-packages/discord/client.py", line 481, in _run_event
    await coro(*args, **kwargs)
  File "/home/container/main.py", line 172, in on_voice_state_update
    await member.send(f"ðŸŽ‰ You've earned {credits_earned} credits for spending {int(time_spent // 60)} minutes in a voice channel!")
  File "/home/container/.local/lib/python3.11/site-packages/discord/abc.py", line 1644, in send
    data = await state.http.send_message(channel.id, params=params)
           ^^^^^^^^^^^^^^^^^^^^^^^^^^^^^^^^^^^^^^^^^^^^^^^^^^^^^^^^
  File "/home/container/.local/lib/python3.11/site-packages/discord/http.py", line 756, in request
    raise Forbidden(response, data)
discord.errors.Forbidden: 403 Forbidden (error code: 50007): Cannot send messages to this user


Error in on_voice_state_update:
Traceback (most recent call last):
  File "/home/container/.local/lib/python3.11/site-packages/aiohttp/connector.py", line 1512, in _create_direct_connection
    hosts = await self._resolve_host(host, port, traces=traces)
            ^^^^^^^^^^^^^^^^^^^^^^^^^^^^^^^^^^^^^^^^^^^^^^^^^^^
  File "/home/container/.local/lib/python3.11/site-packages/aiohttp/connector.py", line 1128, in _resolve_host
    return await asyncio.shield(resolved_host_task)
           ^^^^^^^^^^^^^^^^^^^^^^^^^^^^^^^^^^^^^^^^
  File "/home/container/.local/lib/python3.11/site-packages/aiohttp/connector.py", line 1159, in _resolve_host_with_throttle
    addrs = await self._resolver.resolve(host, port, family=self._family)
            ^^^^^^^^^^^^^^^^^^^^^^^^^^^^^^^^^^^^^^^^^^^^^^^^^^^^^^^^^^^^^
  File "/home/container/.local/lib/python3.11/site-packages/aiohttp/resolver.py", line 40, in resolve
    infos = await self._loop.getaddrinfo(
            ^^^^^^^^^^^^^^^^^^^^^^^^^^^^^
  File "/usr/local/lib/python3.11/asyncio/base_events.py", line 868, in getaddrinfo
    return await self.run_in_executor(
           ^^^^^^^^^^^^^^^^^^^^^^^^^^^
  File "/usr/local/lib/python3.11/concurrent/futures/thread.py", line 58, in run
    result = self.fn(*self.args, **self.kwargs)
             ^^^^^^^^^^^^^^^^^^^^^^^^^^^^^^^^^^
  File "/usr/local/lib/python3.11/socket.py", line 974, in getaddrinfo
    for res in _socket.getaddrinfo(host, port, family, type, proto, flags):
               ^^^^^^^^^^^^^^^^^^^^^^^^^^^^^^^^^^^^^^^^^^^^^^^^^^^^^^^^^^^
socket.gaierror: [Errno -3] Temporary failure in name resolution

The above exception was the direct cause of the following exception:

Traceback (most recent call last):
  File "/home/container/.local/lib/python3.11/site-packages/discord/client.py", line 481, in _run_event
    await coro(*args, **kwargs)
  File "/home/container/main.py", line 172, in on_voice_state_update
    await member.send(f"ðŸŽ‰ You've earned {credits_earned} credits for spending {int(time_spent // 60)} minutes in a voice channel!")
  File "/home/container/.local/lib/python3.11/site-packages/discord/abc.py", line 1594, in send
    channel = await self._get_channel()
              ^^^^^^^^^^^^^^^^^^^^^^^^^
  File "/home/container/.local/lib/python3.11/site-packages/discord/member.py", line 414, in _get_channel
    ch = await self.create_dm()
         ^^^^^^^^^^^^^^^^^^^^^^
  File "/home/container/.local/lib/python3.11/site-packages/discord/member.py", line 194, in general
    return await getattr(self._user, x)(*args, **kwargs)
           ^^^^^^^^^^^^^^^^^^^^^^^^^^^^^^^^^^^^^^^^^^^^^
  File "/home/container/.local/lib/python3.11/site-packages/discord/user.py", line 569, in create_dm
    data: DMChannelPayload = await state.http.start_private_message(self.id)
                             ^^^^^^^^^^^^^^^^^^^^^^^^^^^^^^^^^^^^^^^^^^^^^^^
  File "/home/container/.local/lib/python3.11/site-packages/discord/http.py", line 642, in request
    async with self.__session.request(method, url, **kwargs) as response:
  File "/home/container/.local/lib/python3.11/site-packages/aiohttp/client.py", line 1482, in __aenter__
    self._resp: _RetType = await self._coro
                           ^^^^^^^^^^^^^^^^
  File "/home/container/.local/lib/python3.11/site-packages/aiohttp/client.py", line 770, in _request
    resp = await handler(req)
           ^^^^^^^^^^^^^^^^^^
  File "/home/container/.local/lib/python3.11/site-packages/aiohttp/client.py", line 725, in _connect_and_send_request
    conn = await self._connector.connect(
           ^^^^^^^^^^^^^^^^^^^^^^^^^^^^^^
  File "/home/container/.local/lib/python3.11/site-packages/aiohttp/connector.py", line 622, in connect
    proto = await self._create_connection(req, traces, timeout)
            ^^^^^^^^^^^^^^^^^^^^^^^^^^^^^^^^^^^^^^^^^^^^^^^^^^^
  File "/home/container/.local/lib/python3.11/site-packages/aiohttp/connector.py", line 1189, in _create_connection
    _, proto = await self._create_direct_connection(req, traces, timeout)
               ^^^^^^^^^^^^^^^^^^^^^^^^^^^^^^^^^^^^^^^^^^^^^^^^^^^^^^^^^^
  File "/home/container/.local/lib/python3.11/site-packages/aiohttp/connector.py", line 1518, in _create_direct_connection
    raise ClientConnectorDNSError(req.connection_key, exc) from exc
aiohttp.client_exceptions.ClientConnectorDNSError: Cannot connect to host discord.com:443 ssl:default [Temporary failure in name resolution]
